Workbook

Sheet READ ME
A1: COREON EDU — MANUAL TEST EXECUTION WORKBOOK
A2: Standard | B2: Test Case Specification + Defect Register, per ISO/IEC/IEEE 29119-3 (formerly IEEE 829).
A3: Phase | B3: Test Design & Test Execution, inside the System Testing stage of the STLC.
A4: Product | B4: Coreon EDU — Kogia Group
A5: Owner | B5: Othman Ounis
A7: THE SHEETS
A8: Dashboard | B8: Read-only. Auto-calculates pass rate, coverage and open defects. Do not type here.
A9: Test Log | B9: THE MAIN SHEET. One row per element tested. This is where you spend your time.
A10: Defect Log | B10: One row per BUG — something that is broken in what already exists. Every FAIL in Test Log points here.
A11: Change Requests | B11: One row per thing to ADD or CHANGE. Not bugs. Enhancements, new features, design, content, epics, research.
A12: Raw Notes (original) | B12: Your notes, kept word for word. Nothing is ever deleted from here — it is the audit trail.
A13: Modules | B13: Inventory of all 46 screens. Tick them off as you cover them. Gives you the coverage %.
A14: Roles & Logins | B14: The 7 demo accounts. Use these, never invent new ones — results must be reproducible.
A15: Test Cycles | B15: One row per round of testing (per release). Records the Go / No-Go decision.
A16: Lists | B16: Source data for the dropdowns. Edit only if you want to change the allowed values.
A18: HOW TO USE IT — THE LOOP
A19: 1. Pick a module | B19: Take one row from the Modules sheet. Test it completely before moving on. Do not jump around.
A20: 2. Pick a role | B20: Test the module as ONE role at a time. The same button can behave differently for a parent and for Direction.
A21: 3. Click everything | B21: Every button, link, tab, dropdown, toggle, icon, table header, modal close. One row in Test Log per element.
A22: 4. Write Expected BEFORE Actual | B22: Decide what SHOULD happen before you click. If you click first, you will accept whatever you see as normal. This is the single most important discipline in this file.
A23: 5. Mark the status | B23: PASS / FAIL / BLOCKED / NOT RUN / N-A. Blocked means you could not test it because something else is broken — it is not a Fail.
A24: 6. Log the defect | B24: Every FAIL gets a row in Defect Log and its ID written back into the Test Log row.
A25: 7. Retest after the fix | B25: Set Retest to PASS or FAIL. Never close a defect without retesting it yourself.
A27: DEFECT vs CHANGE REQUEST — THE MOST IMPORTANT DISTINCTION IN THIS FILE
A28: A DEFECT is | B28: The product does not do what it was supposed to do. Something is broken. It goes in the Defect Log.
A29: A CHANGE REQUEST is | B29: The product works as designed, but the design itself should change. Nothing is broken. It goes in Change Requests.
A30: Why keep them apart | B30: They are decided by different people, cost different money, and answer different questions. A defect asks 'when is it fixed'. A change request asks 'do we even want it, and is it worth the price'. Mixing them into one list is the fastest way to lose control of a product.
A31: The test | B31: Ask: was it ever meant to work this way? If yes and it does not -> defect. If it works as intended and you simply want something else -> change request.
A32: Example - defect | B32: The login page does not fit the browser window. It was never meant to overflow. DEF-001.
A33: Example - change request | B33: Make the weather widget smaller. It works exactly as built; you want a different design. CR-015.
A35: SEVERITY vs PRIORITY — THEY ARE NOT THE SAME
A36: Severity | B36: How much damage the bug does. Set by the tester. Critical / Major / Minor / Trivial.
A37: Priority | B37: How fast it must be fixed. Set by the product owner. P1 / P2 / P3 / P4.
A38: Example | B38: A typo on the landing page is Trivial severity — but P1 priority if a school is visiting the site tomorrow.
A40: SEVERITY SCALE
A41: Critical | B41: Data loss, data leak between roles, money is wrong, or the app cannot be used at all. Stop the release.
A42: Major | B42: A main function does not work, and there is no workaround.
A43: Minor | B43: A function works but behaves wrongly, or there is an acceptable workaround.
A44: Trivial | B44: Cosmetic: spacing, wording, colour, alignment.
A46: RULES THAT MAKE THIS WORKBOOK WORTH KEEPING
...

Sheet Dashboard
B2: COREON EDU — QA DASHBOARD
B3: Read-only — every number is calculated from the other sheets. Do not type in column C.
B5: TEST EXECUTION
B6: Test cases logged | C6: =COUNTA('Test Log'!A3:A600) | F6: Rows filled in the Test Log
B7: Executed | C7: =COUNTIFS('Test Log'!T3:T600,"PASS")+COUNTIFS('Test Log'!T3:T600,"FAIL")+COUNTIFS('Test Log'!T3:T600,"BLOCKED") | F7: Pass + Fail + Blocked
B8: Passed | C8: =COUNTIF('Test Log'!T3:T600,"PASS")
B9: Failed | C9: =COUNTIF('Test Log'!T3:T600,"FAIL")
B10: Blocked | C10: =COUNTIF('Test Log'!T3:T600,"BLOCKED") | F10: Could not be tested — not the same as a failure
B11: Not run | C11: =COUNTIF('Test Log'!T3:T600,"NOT RUN")
B12: Pass rate | C12: =IF(C7=0,"",C8/C7) | F12: Passed / executed
B13: Execution progress | C13: =IF(C6=0,"",C7/C6) | F13: Executed / logged
B15: DEFECTS
B16: Total defects | C16: =COUNTA('Defect Log'!A3:A400)
B17: Open | C17: =COUNTA('Defect Log'!A3:A400)-COUNTIFS('Defect Log'!U3:U400,"CLOSED")-COUNTIFS('Defect Log'!U3:U400,"WON'T FIX")-COUNTIFS('Defect Log'!U3:U400,"DUPLICATE")-COUNTIFS('Defect Log'!U3:U400,"NOT A BUG")
B18: Open Critical | C18: =COUNTIFS('Defect Log'!O3:O400,"Critical",'Defect Log'!U3:U400,"<>CLOSED") | F18: MUST be 0 before any release
B19: Open Major | C19: =COUNTIFS('Defect Log'!O3:O400,"Major",'Defect Log'!U3:U400,"<>CLOSED")
B20: Open Minor | C20: =COUNTIFS('Defect Log'!O3:O400,"Minor",'Defect Log'!U3:U400,"<>CLOSED")
B21: Open Trivial | C21: =COUNTIFS('Defect Log'!O3:O400,"Trivial",'Defect Log'!U3:U400,"<>CLOSED")
B22: P1 outstanding | C22: =COUNTIFS('Defect Log'!P3:P400,"P1 - Immediate",'Defect Log'!U3:U400,"<>CLOSED")
B23: Awaiting retest | C23: =COUNTIF('Defect Log'!U3:U400,"READY TO RETEST")
B24: Reopened | C24: =COUNTIF('Defect Log'!U3:U400,"REOPENED") | F24: High reopen count = fixes are not verified
B26: MODULE COVERAGE
B27: Modules total | C27: =COUNTA(Modules!B3:B60)
B28: Complete | C28: =COUNTIF(Modules!G3:G60,"Complete")
B29: In progress | C29: =COUNTIF(Modules!G3:G60,"In progress")
B30: Not started | C30: =COUNTIF(Modules!G3:G60,"Not started")
B31: Blocked | C31: =COUNTIF(Modules!G3:G60,"Blocked")
B32: Modules complete % | C32: =IF(C27=0,"",C28/C27)
B33: Elements identified | C33: =SUM(Modules!H3:H60)
B34: Elements tested | C34: =SUM(Modules!I3:I60)
B35: Element coverage % | C35: =IF(C33=0,"",C34/C33) | F35: The real 'have I clicked everything' number
B37: EXIT CRITERIA — may we release?
B38: No test case left Not Run | C38: =IF(C11=0,"MET","NOT MET")
B39: Zero open Critical defects | C39: =IF(C18=0,"MET","NOT MET")
B40: Zero open P1 defects | C40: =IF(C22=0,"MET","NOT MET")
B41: Pass rate at or above 95% | C41: =IF(N(C12)>=0.95,"MET","NOT MET")
B42: All modules Complete or Out of scope | C42: =IF(C30+C29+C31=0,"MET","NOT MET")
B43: Every fixed defect retested | C43: =IF(C23=0,"MET","NOT MET")
B45: VERDICT: release only when every line above says MET. If you override it, write down who decided and why — in Test Cycles.
B47: CHANGE REQUESTS
...

Sheet Test Log
A1: TEST LOG — one row per element tested. Fill Expected result BEFORE you click. Every FAIL needs a Defect ID.
A2: Test ID | B2: Date | C2: Tester | D2: Build / Commit | E2: Environment | F2: Browser / Device | G2: Module / Feature | H2: Sub-module | I2: Screen / Page | J2: Route (URL) | K2: Element type | L2: Element name (label on screen) | M2: Role under test | N2: Test title | O2: Preconditions | P2: Test steps | Q2: Test data | R2: Expected result | S2: Actual result | T2: Status | U2: Severity | V2: Priority | W2: Defect ID | X2: Evidence (screenshot / file) | Y2: Retest | Z2: Retest date | AA2: Comments
A3: TC-001 | B3: =TODAY() | C3: Othman | D3: 50d4c48 | E3: Local dev | F3: Desktop Chrome | G3: Authentication | H3: Login | I3: Login | J3: #/login | K3: Form submit | L3: Se connecter (submit button) | M3: not logged in | N3: Login is refused with a wrong password | O3: App is open at #/login. Demo data seeded. | P3: 1. Type parent@alnour.tn in E-mail 2. Type wrongpass in Mot de passe 3. Click Se connecter | Q3: parent@alnour.tn / wrongpass | R3: Error message 'E-mail ou mot de passe incorrect.' is shown. User stays on #/login. No session created. | T3: NOT RUN | Y3: Not retested | AA3: Example row — delete or overwrite
A4: TC-002 | B4: =TODAY() | C4: Othman | D4: 50d4c48 | E4: Local dev | F4: Mobile Chrome 390px | G4: Évaluation | H4: Save step | I4: Evaluate | J4: #/app/evaluate | K4: Button | L4: Enregistrer | M4: teacher | N4: Saving with zero students placed is blocked | O4: Logged in as enseignant@alnour.tn. A slot is selected. No student dragged into any bucket. | P4: 1. Open #/app/evaluate 2. Select the live slot 3. Place no student 4. Click Enregistrer | Q4: Class CP-A, no placements | R4: An error toast appears, nothing is saved, no parent notification is sent, the button stays enabled. | T4: NOT RUN | Y4: Not retested | AA4: Example row — delete or overwrite

Sheet Defect Log
A1: DEFECT LOG — one row per bug. Severity = how bad the damage (tester decides). Priority = how fast to fix (owner decides). They are not the same.
A2: Defect ID | B2: Date found | C2: Found by | D2: Linked Test ID | E2: Build / Commit | F2: Module / Feature | G2: Screen / Page | H2: Route (URL) | I2: Element | J2: Role | K2: Summary (one line) | L2: Steps to reproduce | M2: Expected result | N2: Actual result | O2: Severity | P2: Priority | Q2: Reproducibility | R2: Environment | S2: Browser / Device | T2: Evidence | U2: Status | V2: Assigned to | W2: Fixed in build | X2: Date closed | Y2: Root cause | Z2: Comments
A3: DEF-001 | B3: =TODAY() | C3: Othman | D3: (raw note 11) | E3: 50d4c48 | F3: Landing & Login | G3: Login | H3: #/login | I3: Whole page | J3: all | K3: The login page does not fit the browser window | L3: 1. Open #/login on a desktop browser 2. Observe the page against the window edges 3. Resize the window | M3: The page fits the viewport at every width, with no horizontal scrollbar and no clipped content. | N3: The layout does not fit the browser window; the page reads as broken. | O3: Major | P3: P2 - High | Q3: Always | R3: edu.kogiagroup.com | S3: Desktop Chrome | U3: CLOSED | V3: Othman | W3: 42601e8 | X3: 2026-07-22 | Z3: Majeur → confirmé MOBILE UNIQUEMENT. Aucun débordement sur ordinateur (1280/1366/1440/1920 = 0). Cause : halo décoratif de 440px sans overflow-hidden. Le grief « ne rentre pas » sur grand écran est un sujet de DESIGN, suivi en CR-011.
A4: DEF-002 | B4: =TODAY() | C4: Othman | D4: (raw note 15) | E4: 50d4c48 | F4: Dashboard | G4: Dashboard | H4: #/app | I4: Several tiles / elements | J4: owner | K4: Several dashboard elements are not clickable | L4: 1. Log in as owner@kogia.tn 2. Open #/app 3. Click each tile, figure and card in turn 4. Note every one that does nothing | M4: Every tile and figure either opens a modal, navigates somewhere, or is visibly non-interactive by design. | N4: Some elements look clickable but do nothing when clicked. | O4: Major | P4: P2 - High | Q4: Always | R4: edu.kogiagroup.com | S4: Desktop Chrome | U4: CLOSED | V4: Othman | W4: 42601e8 | X4: 2026-07-22 | Z4: Requalifié. Aucun élément TROMPEUR sur les 7 tableaux de bord. Réel : 3 chiffres de la console plateforme sans `to` ni `onClick` → rendus en <div> inerte. Les 4 mènent désormais à #/app/schools (vérifié en production).
A5: DEF-003 | B5: =TODAY() | C5: Othman | D5: (raw note 6) | E5: 50d4c48 | F5: Landing & Login | G5: Landing | H5: #/ | I5: Anchor nav: Deux mondes / Modules / Vos données / Tarifs / FAQ | J5: public | K5: Landing anchor navigation gives no feedback that anything happened | L5: 1. Open the landing page 2. Click 'Modules' in the nav 3. Observe the nav and the URL | M5: The clicked item is visibly marked as active and the user can tell the view changed. | N5: The page only scrolls; nothing in the nav changes, so the click feels like it did nothing. | O5: Minor | P5: P3 - Medium | Q5: Always | R5: edu.kogiagroup.com | S5: Desktop Chrome | U5: CLOSED | V5: Othman | W5: 42601e8 | X5: 2026-07-22 | Z5: Requalifié MINEUR → MAJEUR. Les liens ne « défilaient » pas : ils ne faisaient RIEN. Incompatibilité <a href=#ancre> / HashRouter — 9 liens morts. Corrigé + état actif ajouté. Vérifié en production : 0 → 1979.
A6: DEF-004 | B6: =TODAY() | C6: Othman | D6: (raw note 19) | E6: 50d4c48 | F6: Dashboard | G6: Dashboard | H6: #/app | I6: 'Coreon Intelligence' heading block | J6: admin | K6: 'Coreon Intelligence — ce que vos données disent cette semaine' is not aligned on one line | L6: 1. Log in as admin@alnour.tn 2. Open #/app 3. Look at the Coreon Intelligence heading | M6: The title and its subtitle sit on a single consistent baseline. | N6: There is a small vertical drop between the two parts; they do not line up. | O6: Trivial | P6: P3 - Medium | Q6: Always | R6: edu.kogiagroup.com | S6: Desktop Chrome | U6: CLOSED | V6: Othman | W6: 42601e8 | X6: 2026-07-22 | Z6: Confirmé. Cause : la ligne de base d'un conteneur flex vient de son premier élément ; ici une icône SVG, sans ligne de base. Icône passée en inline.

Sheet Change Requests
A1: CHANGE REQUEST LOG — things to ADD or CHANGE (the product works, but it should be different). A defect is 'it does not do what it should'. A change request is 'what it should do must change'.
A2: CR ID | B2: Date raised | C2: Raised by | D2: Raw note # | E2: Type | F2: Epic / Theme | G2: Title | H2: What was asked (your words, tidied) | I2: Why it matters | J2: Area / Module | K2: Route (URL) | L2: Roles affected | M2: Priority | N2: Effort | O2: Status | P2: Target release | Q2: Depends on | R2: Acceptance criteria (how we know it is done) | S2: Linked defect | T2: Comments
A3: CR-001 | B3: =TODAY() | C3: Othman | D3: 1 | E3: Content | F3: Content & tone | G3: Remove the em dash (—) from all product copy | H3: Remove the '—' character everywhere it appears in product content. | I3: Consistent typography; the em dash reads as machine-written and is awkward in French and Arabic. | J3: All modules | K3: Global | L3: all | M3: P3 - Medium | N3: S | O3: TRIAGED | R3: Grep the whole repo (app, core, mobile, i18n) for '—'. Zero occurrences remain in user-facing strings. Both fr and ar locale files verified. No layout breaks from the replacement punctuation. | T3: PAS un remplacer-tout. 1108 occurrences : 457 en commentaires (à laisser), 49 dans t() — où la chaîne FRANÇAISE est la CLÉ de traduction : la modifier casse l'arabe en silence, sans qu'aucun test n'échoue. Il faut modifier l'appel ET la clé i18n.js dans le même geste, et choisir au cas par cas (· ici, virgule là). ~600 décisions : mérite une passe dédiée.
A4: CR-002 | B4: =TODAY() | C4: Othman | D4: 2 | E4: Content | F4: Landing & login | G4: Clarify or rename the 'Deux mondes' section | H4: The section title 'Deux mondes' is not self-explanatory; a visitor cannot tell what it means. | I4: The landing page has about five seconds to be understood. An unclear heading loses the visitor. | J4: Landing | K4: https://edu.kogiagroup.com/ | L4: public | M4: P2 - High | N4: S | O4: DONE | P4: 2026-07-23 | R4: A reader who has never seen Coreon understands what the section offers from the heading alone, without scrolling. Tested on three people who do not know the product. | T4: Le libellé de menu « Deux mondes » devient « Crèche & primaire ». Déployé.
A5: CR-003 | B5: =TODAY() | C5: Othman | D5: 3 | E5: Enhancement | F5: Internationalisation | G5: Show pricing in EUR instead of TND | H5: Convert the pricing cards to euro. | I5: Required for the European positioning; TND signals a local-only product. | J5: Landing / Settings | K5: https://edu.kogiagroup.com/ | L5: public, schooladmin | M5: P2 - High | N5: M | O5: DONE | P5: 2026-07-23 | R5: Pricing displays in EUR with correct formatting. Currency is driven by the settings currency field, not hard-coded. Existing TND schools are unaffected. | T5: Tarifs de la page d’accueil en euros (plus de TND). Déployé.
A6: CR-004 | B6: =TODAY() | C6: Othman | D6: 4 | E6: Enhancement | F6: Internationalisation | G6: Remove Tunisia-specific content from the product | H6: Eliminate the Tunisian framing from all product content and elements. | I6: Positions the product for an international market rather than one country. | J6: All modules | K6: Global | L6: all | M6: P2 - High | N6: L | O6: DONE | P6: 2026-07-23 | R6: No Tunisian governorate list, CIN-only identity, TND-only currency, Tunisia-specific request types or '© 2026 Tunisie' footer is forced on a new school. Each becomes a configurable locale pack. Tunisia remains available as one option, not the default assumption. | T6: core/src/locales.js : packs de pays. tunisia.js délègue au pack actif. La Tunisie reste le défaut, intacte. Déployé.
A7: CR-005 | B7: =TODAY() | C7: Othman | D7: 5 | E7: Epic | F7: Internationalisation | G7: Reposition Coreon EDU for the European market | H7: Redirect the product to be international, European-facing. | I7: Strategic direction for the whole product; drives CR-003, CR-004 and the compliance work. | J7: All modules | K7: Global | L7: all | M7: P1 - Immediate | N7: XL | O7: DONE | P7: 2026-07-23 | R7: A written positioning decision exists: target countries, languages, currency, and the compliance regime (GDPR rather than loi 2004-63). Every child CR references it. Landing copy, pricing, identity fields and legal text all follow from it. | T7: Sélecteur de PAYS dans les paramètres (Tunisie/France/International) pilotant régions, pièce d’identité, cadre légal, devise. Déployé.
A8: CR-006 | B8: =TODAY() | C8: Othman | D8: 6 | E8: Enhancement | F8: Landing & login | G8: Replace the one-page anchor nav with real pages | H8: Clicking Deux mondes / Modules / Vos données / Tarifs / FAQ only scrolls the same page. It should feel like navigating to a different place. | I8: Anchor-only navigation feels unresponsive and gives each topic no shareable URL and no SEO value. | J8: Landing | K8: https://edu.kogiagroup.com/ | L8: public | M8: P2 - High | N8: M | O8: TRIAGED | R8: Each nav item leads to its own routed page with its own URL that can be shared and bookmarked. The browser back button works. The active item is marked in the nav. | S8: DEF-003 | T8: Le défaut « rien ne change au clic » est corrigé (DEF-003 : les ancres défilent + état actif). Des PAGES routées séparées avec URL propres restent un chantier plus large (SEO), à décider.
A9: CR-007 | B9: =TODAY() | C9: Othman | D9: 7 | E9: Design | F9: Pre-enrolment | G9: Widen the pre-enrolment form layout | H9: The form is too narrow; use more of the horizontal space on left and right. | I9: A cramped public form is the first impression a parent gets of the school's software. | J9: Pre-enrolment | K9: #/inscription | L9: public | M9: P3 - Medium | N9: S | O9: DONE | P9: 42601e8 · 2026-07-22 | R9: The form uses a wider container on desktop, stays readable (line length under ~75 characters), and still shows zero horizontal overflow at 390 px. | T9: Formulaire élargi (max-w-2xl → max-w-4xl). Vérifié : toujours 0 débordement à 390px.
A10: CR-008 | B10: =TODAY() | C10: Othman | D10: 8 | E10: New feature | F10: Pre-enrolment | G10: Extend the pre-enrolment form with full family and health details | H10: Add fields modelled on a standard preschool registration form: child first/last name, date of birth, gender, full home address; mother and father each with name, phone and address; health conditions (allergies, illness, disability) with a free-text description; anything else the teachers should know; preferred programme (days per week, before/after school care). | I10: The current form captures the minimum. A school cannot make an admission decision from it, and the data has to be re-collected by hand later. | J10: Pre-enrolment | K10: #/inscription | L10: public, schooladmin, admin | M10: P1 - Immediate | N10: L | O10: DONE | P10: 2026-07-23 | R10: All new fields are captured, validated, persisted, and visible in the Admissions detail modal. Required vs optional is explicit. The health section is stored with the same protection as other health data. The form still submits successfully with only the required fields filled. | T10: Formulaire de pré-inscription enrichi : famille complète, santé, adresse structurée avec pays. Déployé.
A11: CR-009 | B11: =TODAY() | C11: Othman | D11: 9 | E11: New feature | F11: Pre-enrolment | G11: Add terms, agreements and consent to the pre-enrolment form | H11: Select the applicable conditions from a standard registration form: fee payment commitment, notice period for withdrawal, immunisation record requirement, the school's right to decline, guardian signature and date, and data-protection consent. | I11: Without an agreed set of terms the pre-enrolment is not a commitment and gives the school no legal footing. | J11: Pre-enrolment | K11: #/inscription | L11: public, schooladmin | M11: P1 - Immediate | N11: M | O11: DONE | P11: 2026-07-23 | R11: Terms are displayed before submission, consent is an explicit action (never pre-ticked), the submission is refused without it, and the accepted version and timestamp are stored with the application. Aligned with the compliance regime chosen in CR-005. | T11: 6 engagements datés et conservés. Déployé.
A12: CR-010 | B12: =TODAY() | C12: Othman | D12: 10 | E12: New feature | F12: Pre-enrolment | G12: Turn pre-enrolment into a multi-step wizard driven by the level | H12: The ten levels (Crèche, Pré-maternelle, Maternelle 1-2, 1ère to 6ème année) fall into categories with different rules and required information. The form should become several steps and ask only what that category needs. | I12: One flat form asking everything for everyone is long, confusing, and collects irrelevant data. | J12: Pre-enrolment | K12: #/inscription | L12: public | M12: P2 - High | N12: L | O12: DONE | P12: 2026-07-23 | R12: Level categories are defined and documented. Choosing a level determines the following steps. Progress is visible, back and forward preserve entered data, and validation runs per step. Depends on CR-008 for the field set. | T12: Formulaire à étapes guidé par le niveau (crèche/maternelle/primaire). Déployé.
A13: CR-011 | B13: =TODAY() | C13: Othman | D13: 11 | E13: Design | F13: Landing & login | G13: Redesign the login page | H13: The login page design needs rework. | I13: The login screen is seen on every single visit by every user; it sets the perceived quality of the product. | J13: Login | K13: #/login | L13: all | M13: P2 - High | N13: M | O13: TRIAGED | R13: A redesign is agreed against the Kogia Harmony brand system, fits every viewport from 390 px upward, and keeps the seven demo role buttons available in demo mode only. The viewport defect DEF-001 is fixed as part of this. | S13: DEF-001 | T13: Le débordement mobile réel est corrigé (DEF-001). La refonte visuelle complète de l’écran de connexion reste un choix de design d’Othman.
A14: CR-012 | B14: =TODAY() | C14: Othman | D14: 12 | E14: Content | F14: Landing & login | G14: Rewrite the login and landing marketing copy | H14: The current copy ('Pas un ERP scolaire de plus', 'L'école qu'on a envie d'ouvrir', the 121 / 96% / 8 figures, 'par Kogia Group © 2026 Tunisie') is not compelling. | I14: This is the first and most repeated text in the product; it carries the positioning. | J14: Landing / Login | K14: #/login | L14: public | M14: P2 - High | N14: M | O14: IN PROGRESS | R14: New copy is written after CR-005 fixes the positioning, drops the Tunisia reference, and states clearly what Coreon does and for whom. Demo statistics are either real or clearly labelled as a demonstration. | T14: Mention « Tunisie » retirée de l’écran de connexion. La réécriture des accroches marketing relève d’un choix éditorial.
A15: CR-013 | B15: =TODAY() | C15: Othman | D15: 13 | E15: New feature | F15: Authentication | G15: Add a password recovery flow | H15: There is no 'forgot password' anywhere. Add one, handled through support@kogiagroup.com. | I15: Without recovery, a locked-out user cannot get back in without a developer. This blocks any real school using the product. | J15: Login | K15: #/login | L15: all | M15: P1 - Immediate | N15: M | O15: DONE | P15: 42601e8 · 2026-07-22 | R15: A 'Mot de passe oublié' link exists on the login page. Submitting an address sends a time-limited, single-use reset link and reveals nothing about whether the account exists. Tokens expire. The flow works in server mode; behaviour in demo mode is explicitly defined. Runs through the existing coreon-mail-worker. | T15: Livré. Serveur : /api/forgot + /api/reset, jeton usage unique 60 min, réponse neutre, 5 demandes/h/IP, compte désactivé ignoré, sessions fermées à la réinitialisation. Web : #/mot-de-passe-oublie + #/reinitialiser + lien sur /login. Mode démo : la demande part à support@kogiagroup.com. 4 tests serveur + 10 vérif. navigateur.
A16: CR-014 | B16: =TODAY() | C16: Othman | D16: 14 | E16: New feature | F16: Owner console | G16: Add a technical corner to each school in the owner console | H16: As Kogia Group, be able to open a school and see its technical details: contact e-mails, domain, IP addresses, ports, configuration; and reach it directly to check what is happening. Start with whatever information exists today. | I16: You operate the platform for every school. Without this you cannot diagnose a customer problem without opening a terminal. | J16: Schools | K16: #/app/schools | L16: owner | M16: P2 - High | N16: L | O16: DONE | P16: 2026-07-23 | R16: Each school row opens a technical panel showing the fields that exist today (name, plan, Direction contact, status, revision, last activity), with clearly marked empty placeholders for the fields not yet collected. Owner-only. Never exposes passwords or personal pupil data. A follow-up CR adds the missing infrastructure fields. | T16: Fiche technique par école dans la console plateforme : ce qu’on a, « à collecter » pour le reste. Déployé.
A17: CR-015 | B17: =TODAY() | C17: Othman | D17: 16 | E17: Design | F17: Shell & chrome | G17: Make the weather widget smaller | H17: The Météo corner is too prominent; reduce its size. | I17: It competes for attention with the working areas of the header. | J17: AppShell | K17: Global | L17: all | M17: P4 - Low | N17: XS | O17: DONE | P17: 42601e8 · 2026-07-22 | R17: The widget is visually secondary to the school name and the notification bell, still legible, and does not wrap the header at 390 px. | T17: Chip météo en une seule ligne (icône 20px + température) ; libellé et détail dans le panneau.
A18: CR-016 | B18: =TODAY() | C18: Othman | D18: 17 | E18: Research | F18: Role model | G18: Define what separates Direction from Administration | H18: The two roles feel like the same platform. The observed split is that Administration creates and receives requests and views evaluation dashboards, while Direction monitors and gives final approval. This needs to be researched and written down properly. | I18: Two roles that overlap confuse users, make permissions arbitrary, and block the departmental split in CR-019. | J18: Access control | K18: Global | L18: schooladmin, admin | M18: P1 - Immediate | N18: M | O18: DONE | P18: 2026-07-23 | R18: A written role definition exists for both: what each one owns, decides, approves and cannot do. It is validated against how real schools are organised. ROUTE_ROLES and WRITE_ACL are updated to match, and the difference is visible in the product, not only in the code. | T18: Tranché et documenté (docs/quality/role-model.md §2) : l’Administration PRÉPARE et enregistre ; la Direction DÉCIDE et approuve. Jamais le même compte sur l’argent ou une action RH. Recherche sourcée (9 références).
A19: CR-017 | B19: =TODAY() | C19: Othman | D19: 18 | E19: Epic | F19: Identity & numbering | G19: Give every record a formal, structured ID | H19: Nothing currently carries a proper identifier. Every entity — student, teacher, request, accident, registration — should have a structured ID following a real numbering convention, not a raw internal key. | I19: Structured IDs are what make an ERP auditable: they can be quoted on paper, searched, and traced. | J19: All modules | K19: Global | L19: all | M19: P1 - Immediate | N19: XL | O19: NEW | R19: A documented numbering scheme exists (prefix, year, sequence, check digit) with one prefix per entity type. IDs are gapless, immutable once issued, never reused, and shown wherever the record appears. Existing demo data is migrated. Follows the pattern already proven in the Documents registry. | T19: SPÉCIFIÉ (plus bloqué par la recherche) : voir docs/quality/role-model.md §7 pour le backlog concret. Reste un chantier de plusieurs semaines qui touche le modèle de données — à planifier avec Othman.
A20: CR-018 | B20: =TODAY() | C20: Othman | D20: 18 | E20: Epic | F20: Identity & numbering | G20: Add a person identity record separate from the entity ID | H20: Two different IDs are needed: the record ID from CR-017, and a real human identity for every person — national ID card or passport — chosen by the parent for a child and by the adult for themselves. | I20: One human can be a parent, an employee and an alumnus at once. Without a person record they become three unrelated rows, and no ERP can work that way. | J20: All modules | K20: Global | L20: all | M20: P1 - Immediate | N20: XL | O20: NEW | R20: A person entity exists, holding identity document type, number, issuing country and expiry, with the document type selectable rather than fixed to CIN. One person links to many roles. Uniqueness is enforced per document type and country. Identity data is treated as sensitive and excluded from staff-facing blobs. Depends on CR-017 and on the compliance regime from CR-005. | T20: SPÉCIFIÉ (plus bloqué par la recherche) : voir docs/quality/role-model.md §7 pour le backlog concret. Reste un chantier de plusieurs semaines qui touche le modèle de données — à planifier avec Othman.
A21: CR-019 | B21: =TODAY() | C21: Othman | D21: 21 | E21: Epic | F21: ERP architecture | G21: Split Administration into real departmental platforms | H21: One Administration platform holding every service is not how a school works — every school has departments, even when one person staffs them. Build genuine platforms for HR, Accounting and Administration. | I21: Departmental separation is what makes it an ERP rather than a collection of screens, and it is the precondition for real separation of duties. | J21: All modules | K21: Global | L21: schooladmin, admin | M21: P1 - Immediate | N21: XL | O21: NEW | R21: Each department has its own workspace, its own role, its own permissions and its own dashboard. A person can hold more than one departmental role. Data crosses departments only through explicit, logged handovers. One person can still run all of them in a small school without extra friction. Depends on CR-016. | T21: SPÉCIFIÉ (plus bloqué par la recherche) : voir docs/quality/role-model.md §7 pour le backlog concret. Reste un chantier de plusieurs semaines qui touche le modèle de données — à planifier avec Othman.
A22: CR-020 | B22: =TODAY() | C22: Othman | D22: 22 | E22: Research | F22: Role model | G22: Map the relationships between every role across every level | H22: Research how Direction, Administration, HR, Accounting, Supervisor, Security, Teacher and Parent relate to each other in a school, across all ten levels from Crèche to 6ème année. | I22: This is the foundation under CR-016, CR-019 and the permission model. Guessing it produces a product that no real school recognises. | J22: Access control | K22: Global | L22: all | M22: P1 - Immediate | N22: L | O22: DONE | P22: 2026-07-23 | R22: A written model exists: who reports to whom, who approves what, which information flows between roles, and how this differs between early years and primary. Backed by real sources, not assumption. It becomes the specification the permission matrix is tested against. | T22: Modèle complet livré (docs/quality/role-model.md) : les 8 rôles POSSÈDE/DÉCIDE/APPROUVE/NE-DOIT-PAS, les chaînes d’approbation, la matrice « ne doit pas voir », et les différences crèche vs primaire. Devient la spéc de CR-019/021.
A23: CR-021 | B23: =TODAY() | C23: Othman | D23: 23 | E23: Epic | F23: ERP architecture | G23: Reposition Coreon EDU as a genuine ERP | H23: The overall direction: move the product from its current state to a real ERP system. | I23: The parent decision that CR-016 through CR-019 all serve. | J23: All modules | K23: Global | L23: all | M23: P1 - Immediate | N23: XL | O23: NEW | R23: A written definition of what 'real ERP' means for Coreon: departments, double-entry accounting, documented identity and numbering, audit trail, separation of duties, and period closing. A gap analysis lists what exists today against that definition, and every child CR traces back to it. | T23: SPÉCIFIÉ (plus bloqué par la recherche) : voir docs/quality/role-model.md §7 pour le backlog concret. Reste un chantier de plusieurs semaines qui touche le modèle de données — à planifier avec Othman.
A24: CR-022 | B24: =TODAY() | C24: Othman | D24: 24 | E24: New feature | F24: Academic | G24: Let a teacher grade a whole class in one screen | H24: In Bulletins & passage, a teacher should be able to enter marks for the entire class across subjects (Mathématiques, Français, Arabe, Éveil scientifique, Anglais, each out of 20) rather than one pupil at a time. | I24: Entering marks pupil by pupil is the single most repetitive task a teacher does; it is where the product either saves time or wastes it. | J24: Academic | K24: #/app/academic | L24: teacher, schooladmin, admin | M24: P1 - Immediate | N24: L | O24: DONE | P24: 2026-07-23 | R24: A grid shows pupils as rows and subjects as columns. Keyboard entry moves down the column. Marks are validated against the subject maximum. Partial entry can be saved and resumed. The subject list follows the level, and totals recalculate live. | T24: Grille de saisie des notes par classe, au clavier, moyennes en direct. Déployé.
A25: CR-023 | B25: 2026-07-23 | C25: Othman | D25: 1 | E25: Enhancement | F25: Internationalisation | G25: Marchés cibles : 4 pays + structure géographique Pays → Ville → École | H25: Restreindre aux 4 marchés de lancement (Bahreïn, Qatar, Tunisie, Libye) au lieu d’un support mondial générique. Cascade Pays → Ville → École : on choisit un pays, le système charge SES villes, on choisit une ville, on configure l’école. Aucune saisie libre de pays/ville. Données pays/villes en données de référence, extensibles. | I25: Un acheteur du Golfe doit voir SON pays et SES villes, pas une liste mondiale ni la Tunisie par défaut. C’est ce qui rend la démo crédible pour Bahreïn/Qatar/Libye. | J25: Paramètres · Onboarding · Console plateforme | K25: #/app/settings · #/app/schools | L25: owner, schooladmin | M25: P1 - Immediate | N25: M | O25: DONE | P25: 5123df2 · 2026-07-23 | Q25: CR-004/005 (packs pays — FAIT), CR-017 (code école — FAIT) | R25: Prolonge directement core/src/locales.js : remplacer les packs de démo FR/INTL par BH/QA/TN/LY + ajouter les villes. Faisable tout de suite, faible risque, fort impact démo. À FAIRE MAINTENANT. | T25: LIVRÉ. 4 pays (BH/QA/TN/LY) avec devise, code ISO, pièce d’identité et cadre légal locaux. Villes en données de référence, cascade Pays→Ville dans les Paramètres. La référence ERP porte le code pays (STD-LY-…). Ajouter un pays = un objet dans locales.js.
A26: CR-024 | B26: 2026-07-23 | C26: Othman | D26: 2 | E26: Epic | F26: ERP architecture | G26: Couche de configuration par pays (langue + système éducatif), un seul cœur | H26: Un cœur ERP unique + des modules de configuration par pays (countries/{bahrain,qatar,tunisia,libye}). Chaque pays personnalise : langues (ordre primaire/secondaire), système éducatif (niveaux, matières, méthode d’évaluation, terminologie, structure de l’année). L’activation d’une école charge la bonne config. JAMAIS 4 bases de code. | I26: Chaque école doit sentir qu’elle a un ERP local conçu pour SON système éducatif, pas un produit étranger traduit. C’est l’argument de vente régional. | J26: Tout le produit | K26: Global | L26: owner, schooladmin | M26: P2 - High | N26: XL | O26: IN PROGRESS | P26: À PHASER | Q26: CR-023 (pays), CR-016/020 (modèle de rôles — FAIT) | R26: À DÉCOUPER. La couche LANGUE existe déjà (i18n + packs pays) → activable vite. La couche CURRICULUM (niveaux/matières/évaluation/terminologie par pays) est le gros œuvre ERP : la faire pays par pays, à mesure que tu signes chaque marché. Ne PAS tout construire d’un coup. | T26: Couche LANGUE livrée avec CR-023 (languages par pays : primaire/secondaire). Reste la couche CURRICULUM (niveaux/matières/évaluation/terminologie par pays) = gros œuvre, à phaser marché par marché. Architecture prête : locales.js EST la couche de config par pays, un seul cœur.
A27: CR-025 | B27: 2026-07-23 | C27: Othman | D27: 3 | E27: Epic | F27: ERP architecture | G27: La « Bible » d’architecture produit + références ERP à étudier | H27: Constitution du produit : plateforme ERP régionale multi-pays / multi-tenant / multi-école / multi-langue (un seul cœur + config par pays). Deux identités (référence ERP vs identité humaine). API-first web+mobile. Sécurité (RBAC, isolation tenant, audit). Prêt IA. + références à étudier (ERPNext Education, Odoo, SAP/NetSuite/Dynamics) pour les PATTERNS, pas les interfaces. | I27: Empêcher les sessions futures d’abîmer l’architecture peu à peu. Chaque changement se vérifie contre la Bible. | J27: Tout le produit | K27: docs/quality/ARCHITECTURE-BIBLE.md | L27: owner | M27: P1 - Immediate | N27: — | O27: DONE | P27: 5123df2 · 2026-07-23 | Q27: CR-004/005/016/017/018/020/023 (déjà faits) | R27: LIVRÉ : docs/quality/ARCHITECTURE-BIBLE.md — la constitution, avec le tableau ÉTAT vs CIBLE (§11), la règle « classer avant de coder » (§12), le séquencement vers la vente (§13) et les références étudiées (§10). À ouvrir avant toute décision d’architecture.

Sheet Modules
A1: MODULE INVENTORY — 51 testable surfaces. Work through them one at a time. Coverage % fills itself from the Tested / Elements found columns.
A2: # | B2: Module / Feature | C2: Route (URL) | D2: Roles that can access | E2: Notes / risk | F2: Owner | G2: Status | H2: Elements found | I2: Tested | J2: Passed | K2: Failed | L2: Coverage % | M2: Last tested | N2: Comments
A3: 1 | B3: Landing page | C3: #/ | D3: public | E3: Marketing, 8 CTAs, FAQ accordion | G3: Not started | L3: =IF(N(H3)=0,"",J3/H3)
A4: 2 | B4: Login | C4: #/login | D4: public | E4: 7 demo role buttons, FR/AR switch | G4: Not started | L4: =IF(N(H4)=0,"",J4/H4)
A5: 3 | B5: Setup wizard | C5: #/setup | D5: schooladmin | E5: First-run; currently outside the auth guard | G5: Not started | L5: =IF(N(H5)=0,"",J5/H5)
A6: 4 | B6: Pre-enrolment (public) | C6: #/inscription | D6: public | E6: Public form + attachments | G6: Not started | L6: =IF(N(H6)=0,"",J6/H6)
A7: 5 | B7: Dashboard | C7: #/app | D7: all 7 | E7: 6 different dashboards in one page | G7: Not started | L7: =IF(N(H7)=0,"",J7/H7)
A8: 6 | B8: Schools (SaaS console) | C8: #/app/schools | D8: owner | G8: Not started | L8: =IF(N(H8)=0,"",J8/H8)
A9: 7 | B9: Settings | C9: #/app/settings | D9: schooladmin | E9: 6 tabs | G9: Not started | L9: =IF(N(H9)=0,"",J9/H9)
A10: 8 | B10: Accounts | C10: #/app/accounts | D10: schooladmin | E10: Last Direction account is protected | G10: Not started | L10: =IF(N(H10)=0,"",J10/H10)
A11: 9 | B11: Students | C11: #/app/students | D11: schooladmin, admin, supervisor, teacher | E11: DataTable + 24-field modal | G11: Not started | L11: =IF(N(H11)=0,"",J11/H11)
A12: 10 | B12: Student profile (360) | C12: #/app/eleve/:id | D12: schooladmin, admin, supervisor, teacher | G12: Not started | L12: =IF(N(H12)=0,"",J12/H12)
A13: 11 | B13: Teachers | C13: #/app/teachers | D13: schooladmin, admin | E13: 14-field add modal | G13: Not started | L13: =IF(N(H13)=0,"",J13/H13)
A14: 12 | B14: Staff attendance | C14: #/app/staff | D14: schooladmin, admin | E14: 3 tabs, CSV export | G14: Not started | L14: =IF(N(H14)=0,"",J14/H14)
A15: 13 | B15: HR | C15: #/app/hr | D15: schooladmin, admin | E15: Payroll: prepare > recalc > validate > paid | G15: Not started | L15: =IF(N(H15)=0,"",J15/H15)
A16: 14 | B16: Accounting | C16: #/app/accounting | D16: schooladmin, admin | E16: Invoices immutable, credit notes | G16: Not started | L16: =IF(N(H16)=0,"",J16/H16)
A17: 15 | B17: Academic | C17: #/app/academic | D17: schooladmin, admin, teacher | E17: Year promotion is irreversible | G17: Not started | L17: =IF(N(H17)=0,"",J17/H17)
A18: 16 | B18: Facilities | C18: #/app/facilities | D18: schooladmin, admin | E18: Booking conflicts | G18: Not started | L18: =IF(N(H18)=0,"",J18/H18)
A19: 17 | B19: Pointage (clock-in) | C19: #/app/pointage | D19: teacher, supervisor, security, admin | G19: Not started | L19: =IF(N(H19)=0,"",J19/H19)
A20: 18 | B20: Evaluate | C20: #/app/evaluate | D20: teacher | E20: FLAGSHIP FLOW — drag & drop, draft autosave | G20: Not started | L20: =IF(N(H20)=0,"",J20/H20)
A21: 19 | B21: Child file | C21: #/app/child | D21: teacher, admin, schooladmin | E21: Pickup authorisations, health | G21: Not started | L21: =IF(N(H21)=0,"",J21/H21)
A22: 20 | B22: Day journal | C22: #/app/journal | D22: teacher, admin, schooladmin, parent | E22: Parent is read-only | G22: Not started | L22: =IF(N(H22)=0,"",J22/H22)
A23: 21 | B23: Results | C23: #/app/results | D23: schooladmin, admin | G23: Not started | L23: =IF(N(H23)=0,"",J23/H23)
A24: 22 | B24: Timetable | C24: #/app/timetable | D24: schooladmin, admin, teacher, parent, supervisor | G24: Not started | L24: =IF(N(H24)=0,"",J24/H24)
A25: 23 | B25: Attendance | C25: #/app/attendance | D25: schooladmin, teacher, admin, supervisor | E25: Roll call + notify parent | G25: Not started | L25: =IF(N(H25)=0,"",J25/H25)
A26: 24 | B26: Homework | C26: #/app/homework | D26: teacher, admin, parent | E26: FEATURE FLAG OFF by default | G26: Not started | L26: =IF(N(H26)=0,"",J26/H26)
A27: 25 | B27: Exams | C27: #/app/exams | D27: schooladmin, admin, teacher, parent | E27: FEATURE FLAG OFF by default | G27: Not started | L27: =IF(N(H27)=0,"",J27/H27)
A28: 26 | B28: Finance | C28: #/app/finance | D28: schooladmin, admin | G28: Not started | L28: =IF(N(H28)=0,"",J28/H28)
A29: 27 | B29: Payments | C29: #/app/payments | D29: parent | E29: Parent can never set status to Payé | G29: Not started | L29: =IF(N(H29)=0,"",J29/H29)
A30: 28 | B30: Live tracking | C30: #/app/live | D30: parent | E30: Route map + time slider | G30: Not started | L30: =IF(N(H30)=0,"",J30/H30)
A31: 29 | B31: Library | C31: #/app/library | D31: schooladmin, admin, teacher | E31: FEATURE FLAG OFF by default | G31: Not started | L31: =IF(N(H31)=0,"",J31/H31)
A32: 30 | B32: Transport | C32: #/app/transport | D32: schooladmin, admin, parent | E32: FEATURE FLAG OFF by default | G32: Not started | L32: =IF(N(H32)=0,"",J32/H32)
A33: 31 | B33: Events | C33: #/app/events | D33: 6 roles | E33: Month calendar | G33: Not started | L33: =IF(N(H33)=0,"",J33/H33)
A34: 32 | B34: Social | C34: #/app/social | D34: 6 roles | E34: LARGEST PAGE — RSVP / quorum / approval state machine | G34: Not started | L34: =IF(N(H34)=0,"",J34/H34)
A35: 33 | B35: Security | C35: #/app/security | D35: security, schooladmin, admin | E35: 5 tabs | G35: Not started | L35: =IF(N(H35)=0,"",J35/H35)
A36: 34 | B36: Incidents | C36: #/app/incidents | D36: supervisor, security, admin, schooladmin | G36: Not started | L36: =IF(N(H36)=0,"",J36/H36)
A37: 35 | B37: Accidents | C37: #/app/accidents | D37: teacher, supervisor, admin, schooladmin, parent | E37: Two-eyes rule | G37: Not started | L37: =IF(N(H37)=0,"",J37/H37)
A38: 36 | B38: Behavior | C38: #/app/behavior | D38: teacher, admin, schooladmin, parent | E38: No ranking allowed | G38: Not started | L38: =IF(N(H38)=0,"",J38/H38)
A39: 37 | B39: Gallery | C39: #/app/gallery | D39: teacher, admin, schooladmin, parent | E39: Photo privacy per parent | G39: Not started | L39: =IF(N(H39)=0,"",J39/H39)
A40: 38 | B40: Canteen | C40: #/app/canteen | D40: teacher, admin, schooladmin, parent | E40: Allergen alerts | G40: Not started | L40: =IF(N(H40)=0,"",J40/H40)
...

Sheet Roles & Logins
A1: THE 7 DEMO ACCOUNTS — always test with these. Never invent accounts: results must be reproducible.
A2: Role (code) | B2: Label in app | C2: Demo e-mail | D2: Password | E2: What to check with this role | F2: Notes
A3: owner | B3: Plateforme | C3: owner@kogia.tn | D3: owner | E3: SaaS console: create a school, suspend it, reset demo data. | F3: Kogia Group level, above the school
A4: schooladmin | B4: Direction | C4: direction@alnour.tn | D4: admin | E4: Everything. Settings, accounts, modules, finance, promotion. | F4: The last active Direction account cannot be disabled
A5: admin | B5: Administration | C5: admin@alnour.tn | D5: office | E5: Office work: invoices, HR, admissions, documents. | F5: No access to Settings or Accounts
A6: teacher | B6: Enseignant | C6: enseignant@alnour.tn | D6: teacher | E6: Evaluate, attendance, behavior, gallery, requests. | F6: Must NOT receive payroll or invoice data
A7: teacher (crèche) | B7: Enseignant | C7: creche@alnour.tn | D7: teacher | E7: Day journal, meals, nap, diaper — early-years modules only. | F7: Level gating: must not see Timetable
A8: supervisor | B8: Surveillant | C8: surveillant@alnour.tn | D8: super | E8: Incidents, attendance, accidents. | F8: Restricted read scope
A9: security | B9: Sécurité | C9: securite@alnour.tn | D9: secu | E9: Visitors, rounds, log book, instructions. | F9: Must NOT see health, evaluations, behavior, photos
A10: parent | B10: Parent | C10: parent@alnour.tn | D10: parent | E10: Own child only: journal, payments, live, gallery, accidents. | F10: p1 has TWO children — use it to test the child selector
A11: parent 2-5 | B11: Parent | C11: parent2..5@alnour.tn | D11: parent | E11: Privacy: must never see another family's child. | F11: Use to prove data isolation

Sheet Test Cycles
A1: TEST CYCLES — one row per round of testing. The Go / No-Go decision is recorded here, with its evidence.
A2: Cycle # | B2: Name / release | C2: Build / Commit | D2: Start date | E2: End date | F2: Tester(s) | G2: Scope tested | H2: Cases run | I2: Passed | J2: Failed | K2: Blocked | L2: Pass rate | M2: Open Critical | N2: Open Major | O2: Go / No-Go | P2: Decided by | Q2: Notes
A3: 1 | B3: Recette QA initiale | C3: 42601e8 | D3: 2026-07-22 | E3: 2026-07-22 | F3: Othman + Claude | G3: Pages publiques (accueil, connexion, pré-inscription) × 6 tailles ; tableaux de bord × 7 rôles ; parcours mot de passe oublié ; suites automatisées complètes. | H3: 26 | I3: 22 | J3: 4 | K3: 0 | L3: =IF(N(H3)=0,"",I3/H3) | M3: 0 | N3: 0 | O3: GO | P3: Othman | Q3: 4 défauts trouvés et corrigés le jour même. 3 demandes livrées. core 54/54 · serveur 15/15 · e2e 131/131 · CI verte · vérifié sur le site réel.
L4: =IF(N(H4)=0,"",I4/H4)
L5: =IF(N(H5)=0,"",I5/H5)
L6: =IF(N(H6)=0,"",I6/H6)
L7: =IF(N(H7)=0,"",I7/H7)
L8: =IF(N(H8)=0,"",I8/H8)
L9: =IF(N(H9)=0,"",I9/H9)
L10: =IF(N(H10)=0,"",I10/H10)
L11: =IF(N(H11)=0,"",I11/H11)
L12: =IF(N(H12)=0,"",I12/H12)
L13: =IF(N(H13)=0,"",I13/H13)
L14: =IF(N(H14)=0,"",I14/H14)
L15: =IF(N(H15)=0,"",I15/H15)
... L60: =IF(N(H60)=0,"",I60/H60)

Sheet Raw Notes (original)
A1: YOUR ORIGINAL NOTES — kept word for word, never edited. Every row below is traced into the Defect Log or the Change Requests sheet.
A2: Note # | B2: Issue as originally written | C2: Location as originally written
A3: 1 | B3: remove this caracter : — from all the product contents | C3: https://edu.kogiagroup.com/
A4: 2 | B4: Deux mondes what's this mean ? | C4: https://edu.kogiagroup.com/
A5: 3 | B5: Tarifs simples : let's convert it to Euro better | C5: https://edu.kogiagroup.com/
A6: 4 | B6: try to eliminate Tunisia atmosphere from all product contents | C6: all product elements
A7: 5 | B7: redirect the product to be international let's say europian | C7: all product elements
A8: 6 | B8: Deux mondes Modules Vos données TarifsFAQ : when I click here nothing is change because all their contents all in same page just scroll down - so I don't like it solve it | C8: https://edu.kogiagroup.com/
A9: 7 | B9: Pré-inscription form design I don’t like make more bigger in left-right sides | C9: https://edu.kogiagroup.com/#/inscription
A10: 8 | B10: Pre-inscription form details : choose some new details from the following info and add them into our pre-inscription form ok ? Preschool Registration Form Child's Name First Last Date of Birth Gender Male Male Home Address Street Address Street Address Line 2 City Region Postal / Zip Code Bahrain Parents Details Mother’s Name First Last Phone ### ### #### Address Street Address Street Address Line 2 City Region Postal / Zip Code Bahrain Father’s Name First Last Phone ### ### #### Address Street Address Street Address Line 2 City Region Postal / Zip Code Bahrain Child Health Conditions Does your child suffer from any allergies, illness, disability or other medical conditions? Yes No If yes, please describe Is there any other information or issues you would like the teachers to know? Preschool Information Please select preffered programs 2 days tuition a week 3 days tuition a week 4 days tuition a week 5 days tuition a week before school care after school care before & after school care SEND | C10: https://edu.kogiagroup.com/#/inscription
A11: 9 | B11: pre-inscription :: please check the following details and pick what it's good for our product like condition or agreements … 2019-20 Celebrating Children Preschool Registration Form Forms will be accepted on or after January 22, 2019 Registration for (choose one): Yellow Class (3 & 4 year old): 9:30-12:00 (Mon. & Wed.) ________ Blue Class (3 & 4 year old): 9:30-12:00 (Tues. & Thurs.) ________ Green Class (4 & 5 year old morning class): 9:30-12:00 (Tues. Wed. & Thurs.) ________ Red Class (4 & 5 year old afternoon class): 12:45-3:15 (Tues. Wed. & Thurs.) ________ Purple High Five: 9:30-12:00 (Mon. Tues. Wed. & Thurs.)________ Child’s Name Preferred Name _______ Primary Phone Address (include City and Zip Code) Date of Birth ________________ _____ _ Parent 1/Legal Guardian Male__________ Female__________ ______ Parent 1 email address ___________________________________________________________ Occupation/Business Name ____________ Parent 1 Work Phone ______________________Parent 1 Cell Phone ____________________ Parent 2/Legal Guardian __________________ Parent 2 email address ___________________________________________________________ Occupation/Business Name Parent 2 Work Phone Name, age and school (if applicable) of siblings… ______ ______________Parent 2 Cell Phone _____________________ Has anyone in your family previously been enrolled at Celebrating Children Preschool? If so, who & when? Has your child attended preschool before? If so, where and how long? **class is only available if I have enough kids to run it. If a Non-Member, would you like to receive information about Shepherd of the Valley Lutheran Church and our activities? Yes_______ No_______ I hereby agree that, if my child is accepted by the school, I will pay the monthly fee in advance, by the 15th of the month, and will cooperate with the school in carrying out any requirements set for the parents. I will notify the school of any changes in the information as entered on this record. I hereby agree to notify the school two weeks in advance of withdrawal, should such an event occur, or pay the difference. An immunization record must be on file before the child may attend. After a trial period, the school reserves the right of dismissing a child who does not fit into the school’s program or whose parents do not cooperate with the school. SIGNED SIGNED Date _____ (Mother or legal guardian) Date ____ (Father or legal guardian) Please attach a check to the completed registration form which includes a $50.00 non-refundable registration fee plus ½ month’s tuition of $65.00 for a total of $115.00 the 3 year old classes or $50.00 non-refundable registration fee plus ½ month’s tuition of $78.00 for a total of $130.00 for the 4 year old classes or $50.00 non-refundable registration fee plus ½ month’s tuition of $92.50 for a total of $142.50 for the High Five class Tuition is refundable until July 1, 2019 for all classes In the event that my child does not get into the session that has been requested, please… ____ put my child’s name on the morning waiting list (3/4’s please circle M & W ____put my child’s name on the afternoon waiting list (only available to 4/5 class) T & Th or ____put my child’s name on both the morning and afternoon waiting lists (only available to 4/5 class) ____remove my child’s registration destroy I am willing to donate and or return my check. (For office use only) REGISTRATION INFORMATION (circle one) to the CCP scholarship fund. Date Paid: _____________________________ Amount Paid: __________________________ Both) Check Number: _________________________ | C11: https://edu.kogiagroup.com/#/inscription
A12: 10 | B12: when the parent choose level each level has his conditions and rules and formats .. So I think we have 4 category right Crèche Pré-maternelle 1ère année -- so better to change the form into several steps because each category has his different details should fill it : Niveau demandé * Crèche Pré-maternelle Maternelle 1 Maternelle 2 1ère année 2ème année 3ème année 4ème année 5ème année 6ème année | C12: https://edu.kogiagroup.com/#/inscription
A13: 11 | B13: page design is terrable and size page not fit the browser page | C13: https://edu.kogiagroup.com/#/login
A14: 12 | B14: those details are not attractive change other things : Pas un ERP scolaire de plus L'école qu'on a envie d'ouvrir. Évaluer une classe en 30 secondes, suivre la journée de son enfant en direct, organiser la vie commune — web et mobile, les mêmes données. Tableau de bord · aujourd'hui 121 Élèves 96% Présence 8 À décider par Kogia Group · © 2026 · Tunisie | C14: https://edu.kogiagroup.com/#/login
... A26: 24 | B26: Bulletins & passage :: how teacher can give notes to all the classroom math english french Mathématiques /20 Français /20 Arabe /20 Éveil scientifique /20 Anglais | C26: https://edu.kogiagroup.com/#/app/academic

Sheet Lists
A1: Status | B1: Severity | C1: Priority | D1: ElementType | E1: TestType | F1: Role | G1: Environment | H1: Device | I1: DefectStatus | J1: Repro | K1: Retest | L1: ModuleStatus | M1: YesNo | N1: Decision | O1: CRType | P1: CRStatus | Q1: Effort
A2: NOT RUN | B2: Critical | C2: P1 - Immediate | D2: Page load | E2: Functional | F2: owner | G2: Local dev | H2: Desktop Chrome | I2: NEW | J2: Always | K2: Not retested | L2: Not started | M2: Yes | N2: GO | O2: Enhancement | P2: NEW | Q2: XS
A3: PASS | B3: Major | C3: P2 - High | D3: Button | E3: UI / Visual | F3: schooladmin | G3: Local build | H3: Desktop Firefox | I3: OPEN | J3: Sometimes | K3: PASS | L3: In progress | M3: No | N3: NO-GO | O3: New feature | P3: TRIAGED | Q3: S
A4: FAIL | B4: Minor | C4: P3 - Medium | D4: Link | E4: Negative | F4: admin | G4: Server mode | H4: Desktop Safari | I4: IN PROGRESS | J4: Once only | K4: FAIL | L4: Complete | N4: GO with conditions | O4: Design | P4: APPROVED | Q4: M
A5: BLOCKED | B5: Trivial | C5: P4 - Low | D5: Form field | E5: Access control | F5: teacher | G5: GitHub Pages | H5: Desktop Edge | I5: FIXED | J5: Not reproduced | L5: Blocked | N5: Pending | O5: Content | P5: IN PROGRESS | Q5: L
A6: N-A | D6: Form submit | E6: Business rule | F6: supervisor | G6: edu.kogiagroup.com | H6: Mobile Chrome 390px | I6: READY TO RETEST | L6: Out of scope | O6: Epic | P6: DONE | Q6: XL
D7: Dropdown | E7: Data integrity | F7: security | H7: Mobile Safari iOS | I7: CLOSED | O7: Research | P7: REJECTED
D8: Checkbox | E8: Responsive | F8: parent | H8: Tablet | I8: REOPENED | P8: DEFERRED
D9: Radio | E9: RTL / Arabic | F9: not logged in | H9: Expo mobile app | I9: WON'T FIX
D10: Toggle | E10: Accessibility | I10: DUPLICATE
D11: Tab | E11: Performance | I11: NOT A BUG
D12: Modal | E12: Security
D13: Table | E13: Regression
D14: Table sort | E14: Exploratory
D15: Search
D16: Filter chip
D17: Stat tile
D18: Icon
D19: Menu
D20: Drag & drop
D21: File upload
D22: Export CSV
D23: Print / PDF
D24: Keyboard shortcut
D25: Notification
D26: Toast
... D29: Error state
